<?xml version="1.0" encoding="utf-8"?>
<!-- =================================================================================== -->
<!-- |    This document was autogenerated by xacro from ur5_robot.urdf.xacro           | -->
<!-- |    EDITING THIS FILE BY HAND IS NOT RECOMMENDED                                 | -->
<!-- =================================================================================== -->
<robot name="combined">
  <!--robots pose-->
  <link name="world"/>

  <joint name="ABB_6640_180_255_pose" type="fixed">
    <parent link="world"/>
    <child link="ABB_6640_180_255_base_link"/>
    <origin rpy="0.0 0.0 0.0" xyz="0 0 0.0254"/><!--ABB_6640_180_255 pedestal-->
  </joint>

  <joint name="ABB_6640_180_255_pedestal_joint" type="fixed">
    <parent link="ABB_6640_180_255_base_link"/>
    <child link="ABB_6640_180_255_pedestal"/>
    <origin rpy="0.0 0.0 0.0" xyz="0 0 -0.0127"/>
  </joint>
  <link name="ABB_6640_180_255_pedestal">
    <collision>
      <origin rpy="0 0 0" xyz="0 0 0"/>
      <geometry>
        <box size="1.2192 1.0668 0.0254"/>
      </geometry>
    </collision>
    <visual name="visual">
      <geometry>
        <box size="1.2192 1.0668 0.0254"/>
      </geometry>
      <material name="orange">
        <color rgba="1 .42 .04 1"/>
      </material>
    </visual>
  </link>

  <link name="Shelf1">
    <visual>
      <geometry>
        <box size="1.0668 0.7366 2"/>
      </geometry>
      <material name="">
        <color rgba="0.72941176470588237 0.14901960784313725 0.1490196078431373 1.0"/>
      </material>
    </visual>
    <collision>
      <geometry>
        <box size="1.0668 0.7366 2"/>
      </geometry>
    </collision>
  </link>
  <joint name="shelf1_pose" type="fixed">
    <parent link="world"/>
    <child link="Shelf1"/>
    <origin rpy="0.0 0.0 0" xyz="-0.0635 -2.6797 1"/>
  </joint>


  <link name="Shelf2">
    <visual>
      <geometry>
        <box size="0.508 1.143 2.286"/>
      </geometry>
      <material name="">
        <color rgba="0.72941176470588237 0.14901960784313725 0.1490196078431373 1.0"/>
      </material>
    </visual>
    <collision>
      <geometry>
        <box size="0.508 1.143 2.286"/>
      </geometry>
    </collision>
  </link>
  <joint name="shelf2_pose" type="fixed">
    <parent link="world"/>
    <child link="Shelf2"/>
    <origin rpy="0.0 0.0 0" xyz="3.3528 -2.0193 1.143"/>
  </joint>


  <link name="Table1">
    <visual>
      <geometry>
        <box size="0.90805 1.905 1.32"/>
      </geometry>
      <material name="">
        <color rgba="0.72941176470588237 0.14901960784313725 0.1490196078431373 1.0"/>
      </material>
    </visual>
    <collision>
      <geometry>
        <box size="0.90805 1.905 1.32"/>
      </geometry>
    </collision>
  </link>
  <joint name="Table1_pose" type="fixed">
    <parent link="world"/>
    <child link="Table1"/>
    <origin rpy="0.0 0.0 0" xyz="-0.542925 1.6637 0.66"/>
  </joint>

  <link name="Table2">
    <visual>
      <geometry>
        <box size="0.6096 1.2192 0.7112"/>
      </geometry>
      <material name="">
        <color rgba="0.72941176470588237 0.14901960784313725 0.1490196078431373 1.0"/>
      </material>
    </visual>
    <collision>
      <geometry>
        <box size="0.6096 1.2192 0.7112"/>
      </geometry>
    </collision>
  </link>
  <joint name="Table2_pose" type="fixed">
    <parent link="world"/>
    <child link="Table2"/>
    <origin rpy="0.0 0.0 0" xyz="0.2159 2.0066 0.3556"/>
  </joint>


  <link name="Wall1">
    <visual>
      <geometry>
        <box size="0.01 6.4 4"/>
      </geometry>
      <material name="">
        <color rgba="0.1490196078431373 0.14901960784313725 0.72941176470588237 1.0"/>
      </material>
    </visual>
    <collision>
      <geometry>
        <box size="0.01 6.4 4"/>
      </geometry>
    </collision>
  </link>
  <joint name="Wall1_pose" type="fixed">
    <parent link="world"/>
    <child link="Wall1"/>
    <origin rpy="0.0 0.0 0" xyz="-1.1303 0 2"/>
  </joint>

  <link name="Wall2">
    <visual>
      <geometry>
        <box size="0.01 6.4 4"/>
      </geometry>
      <material name="">
        <color rgba="0.1490196078431373 0.14901960784313725 0.72941176470588237 1.0"/>
      </material>
    </visual>
    <collision>
      <geometry>
        <box size="0.01 6.4 4"/>
      </geometry>
    </collision>
  </link>
  <joint name="Wall2_pose" type="fixed">
    <parent link="world"/>
    <child link="Wall2"/>
    <origin rpy="0.0 0.0 0" xyz="3.8227 0 2"/>
  </joint>

  <link name="Wall3">
    <visual>
      <geometry>
        <box size="4.953 0.01 4"/>
      </geometry>
      <material name="">
        <color rgba="0.1490196078431373 0.14901960784313725 0.72941176470588237 1.0"/>
      </material>
    </visual>
    <collision>
      <geometry>
        <box size="4.953 0.01 4"/>
      </geometry>
    </collision>
  </link>
  <joint name="Wall3_pose" type="fixed">
    <parent link="world"/>
    <child link="Wall3"/>
    <origin rpy="0.0 0.0 0" xyz="1.3462 -3.2 2"/>
  </joint>


  <link name="Wall4">
    <visual>
      <geometry>
        <box size="4.953 0.01 4"/>
      </geometry>
      <material name="">
        <color rgba="0.1490196078431373 0.14901960784313725 0.72941176470588237 1.0"/>
      </material>
    </visual>
    <collision>
      <geometry>
        <box size="4.953 0.01 4"/>
      </geometry>
    </collision>
  </link>
  <joint name="Wall4_pose" type="fixed">
    <parent link="world"/>
    <child link="Wall4"/>
    <origin rpy="0.0 0.0 0" xyz="1.3462 3.2 2"/>
  </joint>


  <link name="Ground">
    <visual>
      <geometry>
        <box size="4.953 6.4 0.01"/>
      </geometry>
      <material name="">
        <color rgba="0.1490196078431373 0.14901960784313725 0.72941176470588237 1.0"/>
      </material>
    </visual>
    <collision>
      <geometry>
        <box size="4.953 6.4 0.01"/>
      </geometry>
    </collision>
  </link>
  <joint name="Ground_pose" type="fixed">
    <parent link="world"/>
    <child link="Ground"/>
    <origin rpy="0.0 0.0 0" xyz="1.3462 0 -0.005"/>
  </joint>



















  <!--ABB_6640_180_255 part-->
  <link name="ABB_6640_180_255_base_link">
    <collision>
      <origin rpy="0 0 0" xyz="-.124 0 .12"/>
      <geometry>
        <box size="1.016 .729 .24"/>
      </geometry>
    </collision>
    <visual name="visual">
      <geometry>
        <mesh filename="model://ABB_6640_180_255/meshes/visual/Base.stl"/>
      </geometry>
      <material name="orange">
        <color rgba="1 .42 .04 1"/>
      </material>
    </visual>
    <inertial>
      <origin rpy="0 0 0" xyz="0 0 .107 "/>
      <mass value="254.138"/>
      <inertia ixx="9.459" ixy="-.018" ixz="-.297" iyy="9.18" iyz=".003" izz="16.946"/>
    </inertial>
  </link>
  <link name="ABB_6640_180_255_link_1">
    <collision>
      <origin rpy="0 0 0" xyz="0 0 -.434"/>
      <geometry>
        <cylinder length=".224" radius=".309"/>
      </geometry>
    </collision>
    <collision>
      <origin rpy="1.571 0 0" xyz=".32 .302 0"/>
      <geometry>
        <cylinder length=".226" radius=".107"/>
      </geometry>
    </collision>
    <collision>
      <origin rpy="0 0 0" xyz="-.127 .127 -.215"/>
      <geometry>
        <cylinder length=".214" radius=".118"/>
      </geometry>
    </collision>
    <collision>
      <origin rpy="0 0 0" xyz="-.278 -.197 -.261"/>
      <geometry>
        <box size=".31 .528 .368"/>
      </geometry>
    </collision>
    <collision>
      <origin rpy="3.142 0 3.142" xyz="-.263 -.183 -.168"/>
      <geometry>
        <box size=".628 .387 .556"/>
      </geometry>
    </collision>
    <collision>
      <origin rpy="0 0 0" xyz=".238 .025 -.371"/>
      <geometry>
        <box size=".436 .328 .192"/>
      </geometry>
    </collision>
    <collision>
      <origin rpy="0 0 0" xyz=".32 .025 -.008"/>
      <geometry>
        <box size=".518 .328 .534"/>
      </geometry>
    </collision>
    <visual name="visual">
      <origin rpy="0 0 0" xyz="0 0 -.78"/>
      <geometry>
        <mesh filename="model://ABB_6640_180_255/meshes/visual/Link1.stl"/>
      </geometry>
      <material name="orange"/>
    </visual>
    <visual name="visual2">
      <origin rpy="0 0 0" xyz="0 0 -.78"/>
      <geometry>
        <mesh filename="model://ABB_6640_180_255/meshes/visual/LinkD1.stl"/>
      </geometry>
      <material name="orange"/>
    </visual>
    <inertial>
      <origin rpy="0 0 0" xyz="-.011 -.038 -.214 "/>
      <mass value="469.323"/>
      <inertia ixx="29.062" ixy="11.518" ixz="3.154" iyy="50.561" iyz="-.943" izz="46.087"/>
    </inertial>
  </link>
  <link name="ABB_6640_180_255_link_2">
    <collision>
      <origin rpy="1.571 0 0" xyz="-.015 -.295 .522"/>
      <geometry>
        <box size=".538 1.429 .311"/>
      </geometry>
    </collision>
    <collision>
      <origin rpy="1.571 0 0" xyz=".092 -.111 .22"/>
      <geometry>
        <box size=".251 .169 .058"/>
      </geometry>
    </collision>
    <visual name="visual">
      <origin rpy="0 0 0" xyz="-.32 0 -.78"/>
      <geometry>
        <mesh filename="model://ABB_6640_180_255/meshes/visual/Link2.stl"/>
      </geometry>
      <material name="orange"/>
    </visual>
    <inertial>
      <origin rpy="0 0 0" xyz=".007 -.174 .441 "/>
      <mass value="153.009"/>
      <inertia ixx="37.57" ixy="-.08" ixz="-.145" iyy="37.47" iyz="-5.325" izz="3.526"/>
    </inertial>
  </link>
  <link name="ABB_6640_180_255_link_3">
    <collision>
      <origin rpy="0 1.571 0" xyz=".017 .249 .14"/>
      <geometry>
        <box size=".14 .14 .262"/>
      </geometry>
    </collision>
    <collision>
      <origin rpy="1.571 0 3.142" xyz="0 -.17 0"/>
      <geometry>
        <cylinder length=".135" radius=".238"/>
      </geometry>
    </collision>
    <collision>
      <origin rpy="1.571 0 0" xyz="0 .018 0"/>
      <geometry>
        <cylinder length=".242" radius=".118"/>
      </geometry>
    </collision>
    <collision>
      <origin rpy="0 1.571 0" xyz="-.2 .077 .19"/>
      <geometry>
        <box size=".405 .534 .171"/>
      </geometry>
    </collision>
    <collision>
      <origin rpy="0 1.571 0" xyz=".061 0 .2"/>
      <geometry>
        <cylinder length=".35" radius=".166"/>
      </geometry>
    </collision>
    <collision>
      <origin rpy="1.571 0 0" xyz="-.187 -.051 -.029"/>
      <geometry>
        <box size=".052 .085 .102"/>
      </geometry>
    </collision>
    <collision>
      <origin rpy="1.571 0 0" xyz=".178 -.051 .015"/>
      <geometry>
        <box size=".052 .109 .102"/>
      </geometry>
    </collision>
    <visual name="visual">
      <origin rpy="0 0 0" xyz="-.32 0 -1.855"/>
      <geometry>
        <mesh filename="model://ABB_6640_180_255/meshes/visual/Link3.stl"/>
      </geometry>
      <material name="orange"/>
    </visual>
    <inertial>
      <origin rpy="0 0 0" xyz="-.045 .022 .139 "/>
      <mass value="212.29"/>
      <inertia ixx="6.575" ixy="-1.029" ixz="-.621" iyy="6.667" iyz=".976" izz="7.699"/>
    </inertial>
  </link>
  <link name="ABB_6640_180_255_link_4">
    <collision>
      <origin rpy="1.571 0 0" xyz="1.1425 -.139 0"/>
      <geometry>
        <cylinder length=".092" radius=".139"/>
      </geometry>
    </collision>
    <collision>
      <origin rpy="1.571 0 0" xyz="1.068 -.139 0"/>
      <geometry>
        <box size=".145 .278 .092"/>
      </geometry>
    </collision>
    <collision>
      <origin rpy="1.571 0 0" xyz="1.1425 .138 0"/>
      <geometry>
        <cylinder length=".075" radius=".139"/>
      </geometry>
    </collision>
    <collision>
      <origin rpy="0 1.571 0" xyz=".21 0 0"/>
      <geometry>
        <cylinder length=".98" radius=".122"/>
      </geometry>
    </collision>
    <collision>
      <origin rpy="1.571 0 0" xyz="1.068 .138 0"/>
      <geometry>
        <box size=".145 .278 .075"/>
      </geometry>
    </collision>
    <collision>
      <origin rpy="0 1.571 0" xyz=".83 -.005 0"/>
      <geometry>
        <box size=".278 .36 .331"/>
      </geometry>
    </collision>
    <visual name="visual">
      <origin rpy="0 0 0" xyz="-.32 0 -2.055"/>
      <geometry>
        <mesh filename="model://ABB_6640_180_255/meshes/visual/Link4.stl"/>
      </geometry>
      <material name="orange"/>
    </visual>
    <inertial>
      <origin rpy="0 0 0" xyz=".606 -.008 0 "/>
      <mass value="185.22"/>
      <inertia ixx="1.744" ixy="-.722" ixz=".014" iyy="30.392" iyz="-.005" izz="31.078"/>
    </inertial>
  </link>
  <link name="ABB_6640_180_255_link_5">
    <collision>
      <origin rpy="-.697 -1.571 .697" xyz=".023 0 0"/>
      <geometry>
        <cylinder length=".307" radius=".107"/>
      </geometry>
    </collision>
    <visual name="visual">
      <origin rpy="0 0 0" xyz="-1.462 0 -2.055"/>
      <geometry>
        <mesh filename="model://ABB_6640_180_255/meshes/visual/Link5.stl"/>
      </geometry>
      <material name="orange"/>
    </visual>
    <inertial>
      <origin rpy="0 0 0" xyz=".039 .001 0 "/>
      <mass value="26.117"/>
      <inertia ixx=".106" ixy="-.005" ixz="0" iyy=".207" iyz="0" izz=".218"/>
    </inertial>
  </link>
  <link name="ABB_6640_180_255_link_6">
    <collision>
      <origin rpy="0 1.571 0" xyz="-.019 0 0"/>
      <geometry>
        <cylinder length=".037" radius=".109"/>
      </geometry>
    </collision>
    <visual name="visual">
      <origin rpy="0 0 0" xyz="-1.662 0 -2.055"/>
      <geometry>
        <mesh filename="model://ABB_6640_180_255/meshes/visual/Link6.stl"/>
      </geometry>
      <material name="orange"/>
    </visual>
    <inertial>
      <origin rpy="0 0 0" xyz="-.019 -.001 0 "/>
      <mass value="3.371"/>
      <inertia ixx=".017" ixy="0" ixz="0" iyy=".009" iyz="0" izz=".009"/>
    </inertial>
  </link>
<!--   <link name="ABB_6640_180_255_tool">
    <visual name="visual">
      <origin rpy="0 0 0" xyz="0 0 0"/>
      <geometry>
        <mesh filename="model://paintgun/meshes/paint_gun.stl" scale="0.001 0.001 0.001"/>
      </geometry>
      <material name="orange"/>
    </visual>
    <collision>
      <origin rpy="0 0 0" xyz="0 0 0"/>
      <geometry>
        <mesh filename="model://paintgun/meshes/paint_gun.stl" scale="0.001 0.001 0.001"/>
      </geometry>
    </collision>
  </link> -->

  
  <!-- end of link list -->
  <!-- joint list -->
  <joint name="ABB_6640_180_255_joint_1" type="revolute">
    <origin rpy="0 0 0" xyz="0 0 0.780"/>
    <axis xyz="0 0 1"/>
    <parent link="ABB_6640_180_255_base_link"/>
    <child link="ABB_6640_180_255_link_1"/>
    <limit effort="0" lower="-2.967" upper="2.967" velocity="1.7453"/>
  </joint>
  <joint name="ABB_6640_180_255_joint_2" type="revolute">
    <origin rpy="0 0 0" xyz="0.320 0 0"/>
    <axis xyz="0 1 0"/>
    <parent link="ABB_6640_180_255_link_1"/>
    <child link="ABB_6640_180_255_link_2"/>
    <limit effort="0" lower="-1.134" upper="1.4855" velocity="1.5707"/>
  </joint>
  <joint name="ABB_6640_180_255_joint_3" type="revolute">
    <origin rpy="0 0 0" xyz="0 0 1.075"/>
    <axis xyz="0 1 0"/>
    <parent link="ABB_6640_180_255_link_2"/>
    <child link="ABB_6640_180_255_link_3"/>
    <limit effort="0" lower="-3.142" upper="1.222" velocity="1.5707"/>
  </joint>
  <joint name="ABB_6640_180_255_joint_4" type="revolute">
    <origin rpy="0 0 0" xyz="0 0 0.2"/>
    <axis xyz="1 0 0"/>
    <parent link="ABB_6640_180_255_link_3"/>
    <child link="ABB_6640_180_255_link_4"/>
    <limit effort="0" lower="-5.236" upper="5.236" velocity="2.9671"/>
  </joint>
  <joint name="ABB_6640_180_255_joint_5" type="revolute">
    <origin rpy="0 0 0" xyz="1.1425 0 0 "/>
    <axis xyz="0 1 0"/>
    <parent link="ABB_6640_180_255_link_4"/>
    <child link="ABB_6640_180_255_link_5"/>
    <limit effort="0" lower="-2.094" upper="2.094" velocity="2.4435"/>
  </joint>
  <joint name="ABB_6640_180_255_joint_6" type="revolute">
    <origin rpy="0 0 0" xyz="0.2 0 0 "/>
    <axis xyz="1 0 0"/>
    <parent link="ABB_6640_180_255_link_5"/>
    <child link="ABB_6640_180_255_link_6"/>
    <limit effort="0" lower="-6.283" upper="6.283" velocity="3.3161"/>
  </joint>
<!--   <joint name="joint_6-tool0" type="fixed">
    <parent link="ABB_6640_180_255_link_6"/>
    <child link="ABB_6640_180_255_tool"/>
    <origin rpy="0 1.57079632679 0" xyz="0 0 0"/>
  </joint> -->
  <!-- end of joint list -->


</robot>
